<?xml version="1.0"?>
<!-- =================================================================================== -->
<!-- |    This document was autogenerated by xacro from two_wheel_robot.xacro          | -->
<!-- |    EDITING THIS FILE BY HAND IS NOT RECOMMENDED                                 | -->
<!-- =================================================================================== -->
<robot name="two_wheel_robot">
  <!-- Robot base -->
  <link name="base_link">
    <visual>
      <geometry>
        <box size="0.6 0.5 0.1" />
      </geometry>
      <material name="base_material">
        <color rgba="0.3 0.3 0.3 1.0" />
      </material>
    </visual>
  </link>

  <!-- Left Wheel -->
  <link name="left_wheel">
    <visual>
      <geometry>
        <cylinder length="0.05" radius="0.1" />
      </geometry>
      <material name="left_wheel_material">
        <color rgba="0.8 0.1 0.1 1.0" />
      </material>
      <origin rpy="0 1.5708 0" xyz="0 0 0.1" />
    </visual>
  </link>

  <!-- Right Wheel -->
  <link name="right_wheel">
    <visual>
      <geometry>
        <cylinder length="0.05" radius="0.1" />
      </geometry>
      <material name="right_wheel_material">
        <color rgba="0.1 0.1 0.8 1.0" />
      </material>
      <origin rpy="0 1.5708 0" xyz="0 0 0.1" />
    </visual>
  </link>

  <!-- Joints -->
  <joint name="left_wheel_joint" type="continuous">
    <parent link="base_link" />
    <child link="left_wheel" />
    <origin xyz="0 0.25 0" />
    <axis xyz="0 1 0" />
  </joint>

  <joint name="right_wheel_joint" type="continuous">
    <parent link="base_link" />
    <child link="right_wheel" />
    <origin xyz="0 -0.25 0" />
    <axis xyz="0 1 0" />
  </joint>

  <!-- IMU Sensor -->
  <link name="imu_link">
    <inertial>
      <origin rpy="0 0 0" xyz="0 0 0" />
      <mass value="0.01" />
      <inertia ixx="0.0001" ixy="0.0" ixz="0.0" iyy="0.0001" iyz="0.0" izz="0.0001" />
    </inertial>
    <visual>
      <geometry>
        <box size="0.05 0.05 0.05" />
      </geometry>
      <material name="imu_material">
        <color rgba="0.0 0.5 0.5 1.0" />
      </material>
      <origin rpy="0 0 0" xyz="0 0 0" />
    </visual>
  </link>

  <joint name="imu_joint" type="fixed">
    <parent link="base_link" />
    <child link="imu_link" />
    <origin rpy="0 0 0" xyz="0 0 0.1" />
  </joint>

  <!-- Gazebo IMU Plugin -->
  <gazebo reference="imu_link">
    <sensor name="imu" type="imu">
      <always_on>1</always_on>
      <update_rate>50</update_rate>
      <visualize>true</visualize>
      <topic>imu/data</topic>
      <enable_metrics>true</enable_metrics>
      <ignition_frame_id>imu_link</ignition_frame_id>
    </sensor>
  </gazebo>

  <gazebo>
    <plugin filename="libignition-gazebo-imu-system" name="ignition::gazebo::systems::Imu" />
  </gazebo>
</robot>